<?xml version="1.0"?>

<robot xmlns:xacro="http://www.ros.org/wiki/xacro">
 <xacro:property name="M_PI" value="3.1415926535897931" />

  <xacro:macro name="handsfree_base">
  <link
    name="base_link">
    <inertial>
      <origin
        xyz="0.00053124 -4.2355E-06 0.072209"
        rpy="0 0 0" />
      <mass
        value="3.3726" />
      <inertia
        ixx="0.022549"
        ixy="-6.1472E-07"
        ixz="0.0033897"
        iyy="0.023205"
        iyz="7.1115E-08"
        izz="0.030836" />
    </inertial>
    <visual>
      <origin
        xyz="0 0 0"
        rpy="0 0 0" />
      <geometry>
        <mesh
          filename="package://handsfree_gazebo/meshes/base_link.STL" />
      </geometry>
      <material
        name="">
        <color
          rgba="0.79216 0.81961 0.93333 1" />
      </material>
    </visual>
    <collision>
      <origin
        xyz="0 0 0"
        rpy="0 0 0" />
      <geometry>
        <mesh
          filename="package://handsfree_gazebo/meshes/base_link.STL" />
      </geometry>
    </collision>
  </link>
  
  
  <!--wheel left -->
  <link
    name="wheel_left_link">
    <inertial>
      <origin
        xyz="-2.7756E-17 0 -0.00045914"
        rpy="0 0 0" />
      <mass
        value="0.068656" />
      <inertia
        ixx="1.8609E-05"
        ixy="5.848E-21"
        ixz="-8.4703E-22"
        iyy="1.8609E-05"
        iyz="1.6148E-22"
        izz="2.8893E-05" />
    </inertial>
    <visual>
      <origin
        xyz="0 0 0"
        rpy="0 0 0" />
      <geometry>
        <mesh
          filename="package://handsfree_gazebo/meshes/wheel_left_link.STL" />
      </geometry>
      <material
        name="">
        <color
          rgba="1 1 1 1" />
      </material>
    </visual>
    <collision>
      <origin
        xyz="0 0 0"
        rpy="0 0 0" />
      <geometry>
        <mesh
          filename="package://handsfree_gazebo/meshes/wheel_left_link.STL" />
      </geometry>
    </collision>
  </link>
  <joint
    name="wheel_left"
    type="continuous">
    <origin
      xyz="-0.08225 0.14246 -0.032"
      rpy="-1.5708 -2.7756E-16 0.5236" />
    <parent
      link="base_link" />
    <child
      link="wheel_left_link" />
    <axis
      xyz="0 0 1" />
  </joint>
  
  <joint
    name="wheel_left_slipping"
    type="continuous">
    <origin
      xyz="0 0 0"
      rpy="0 1.5708 0" />
    <parent
      link="wheel_left_link" />
    <child
      link="wheel_left_link_slipping" />
    <axis
      xyz="0 0 1" />
  </joint>
  
  <link
    name="wheel_left_link_slipping">
    <inertial>
      <origin
        xyz="-2.7756E-17 0 -0.00045914"
        rpy="0 0 0" />
      <mass
        value="0.068656" />
      <inertia
        ixx="1.8609E-05"
        ixy="5.848E-21"
        ixz="-8.4703E-22"
        iyy="1.8609E-05"
        iyz="1.6148E-22"
        izz="2.8893E-05" />
    </inertial>
    <collision>
      <origin
        xyz="0 0 0"
        rpy="0 0 0" />
      <geometry>
        <mesh
          filename="package://handsfree_gazebo/meshes/wheel_left_link.STL" />
      </geometry>
    </collision>
  </link>
  
  
  
  
   <!--wheel right -->
  <link
    name="wheel_right_link">
    <inertial>
      <origin
        xyz="0 0 -0.00045914"
        rpy="0 0 0" />
      <mass
        value="0.068656" />
      <inertia
        ixx="1.8609E-05"
        ixy="2.7894E-21"
        ixz="-1.6941E-21"
        iyy="1.8609E-05"
        iyz="-3.4644E-22"
        izz="2.8893E-05" />
    </inertial>
    <visual>
      <origin
        xyz="0 0 0"
        rpy="0 0 0" />
      <geometry>
        <mesh
          filename="package://handsfree_gazebo/meshes/wheel_right_link.STL" />
      </geometry>
      <material
        name="">
        <color
          rgba="1 1 1 1" />
      </material>
    </visual>
    <collision>
      <origin
        xyz="0 0 0"
        rpy="0 0 0" />
      <geometry>
        <mesh
          filename="package://handsfree_gazebo/meshes/wheel_right_link.STL" />
      </geometry>
    </collision>
  </link>
  <joint
    name="wheel_right"
    type="continuous">
    <origin
      xyz="-0.08225 -0.14246 -0.032"
      rpy="1.5708 1.1102E-16 -0.5236" />
    <parent
      link="base_link" />
    <child
      link="wheel_right_link" />
    <axis
      xyz="0 0 1" />
  </joint>
  
  <joint
    name="wheel_right_slipping"
    type="continuous">
    <origin
      xyz="0 0 0"
      rpy="0 1.5708 0" />
    <parent
      link="wheel_right_link" />
    <child
      link="wheel_right_link_slipping" />
    <axis
      xyz="0 0 1" />
  </joint>
  
  <link
    name="wheel_right_link_slipping">
    <inertial>
      <origin
        xyz="-2.7756E-17 0 -0.00045914"
        rpy="0 0 0" />
      <mass
        value="0.068656" />
      <inertia
        ixx="1.8609E-05"
        ixy="5.848E-21"
        ixz="-8.4703E-22"
        iyy="1.8609E-05"
        iyz="1.6148E-22"
        izz="2.8893E-05" />
    </inertial>
    <collision>
      <origin
        xyz="0 0 0"
        rpy="0 0 0" />
      <geometry>
        <mesh
          filename="package://handsfree_gazebo/meshes/wheel_right_link.STL" />
      </geometry>
    </collision>
  </link>
  
  
  
  
  
  
  <!--wheel front-->
  <link
    name="wheel_front_link">
    <inertial>
      <origin
        xyz="3.3791E-17 -6.9389E-18 -0.00045914"
        rpy="0 0 0" />
      <mass
        value="0.068656" />
      <inertia
        ixx="1.8609E-05"
        ixy="1.8722E-21"
        ixz="-4.2765E-21"
        iyy="1.8609E-05"
        iyz="3.2895E-22"
        izz="2.8893E-05" />
    </inertial>
    <visual>
      <origin
        xyz="0 0 0"
        rpy="0 0 0" />
      <geometry>
        <mesh
          filename="package://handsfree_gazebo/meshes/wheel_front_link.STL" />
      </geometry>
      <material
        name="">
        <color
          rgba="1 1 1 1" />
      </material>
    </visual>
    <collision>
      <origin
        xyz="0 0 0"
        rpy="0 0 0" />
      <geometry>
        <mesh
          filename="package://handsfree_gazebo/meshes/wheel_front_link.STL" />
      </geometry>
    </collision>
  </link>
  <joint
    name="wheel_front"
    type="continuous">
    <origin
      xyz="0.1645 0 -0.032"
      rpy="1.5708 0 1.5708" />
    <parent
      link="base_link" />
    <child
      link="wheel_front_link" />
    <axis
      xyz="0 0 1" />
  </joint>
  
  <joint
    name="wheel_front_slipping"
    type="continuous">
    <origin
      xyz="0 0 0"
      rpy="0 1.5708 0" />
    <parent
      link="wheel_front_link" />
    <child
      link="wheel_front_link_slipping" />
    <axis
      xyz="0 0 1" />
  </joint>
  
  <link
    name="wheel_front_link_slipping">
    <inertial>
      <origin
        xyz="-2.7756E-17 0 -0.00045914"
        rpy="0 0 0" />
      <mass
        value="0.068656" />
      <inertia
        ixx="1.8609E-05"
        ixy="5.848E-21"
        ixz="-8.4703E-22"
        iyy="1.8609E-05"
        iyz="1.6148E-22"
        izz="2.8893E-05" />
    </inertial>
    <collision>
      <origin
        xyz="0 0 0"
        rpy="0 0 0" />
      <geometry>
        <mesh
          filename="package://handsfree_gazebo/meshes/wheel_front_link.STL" />
      </geometry>
    </collision>
  </link>
  
  <link
    name="laser_link">
    <inertial>
      <origin
        xyz="-0.0034294 -1.7992E-10 -0.0064564"
        rpy="0 0 0" />
      <mass
        value="0.14728" />
      <inertia
        ixx="6.2168E-05"
        ixy="2.8308E-12"
        ixz="5.4164E-06"
        iyy="8.3311E-05"
        iyz="3.0404E-13"
        izz="0.00011395" />
    </inertial>
    <visual>
      <origin
        xyz="0 0 0"
        rpy="0 0 0" />
      <geometry>
        <mesh
          filename="package://handsfree_gazebo/meshes/laser_link.STL" />
      </geometry>
      <material
        name="">
        <color
          rgba="0.75294 0.75294 0.75294 1" />
      </material>
    </visual>
    <collision>
      <origin
        xyz="0 0 0"
        rpy="0 0 0" />
      <geometry>
        <mesh
          filename="package://handsfree_gazebo/meshes/laser_link.STL" />
      </geometry>
    </collision>
  </link>
  <joint
    name="laser"
    type="fixed">
    <origin
      xyz="0.1425 0 0.0516"
      rpy="0 0 6.314E-15" />
    <parent
      link="base_link" />
    <child
      link="laser_link" />
    <axis
      xyz="0 0 0" />
  </joint>
  <link
    name="servo_1_link">
    <inertial>
      <origin
        xyz="-4.344E-09 1.1292E-09 0.028223"
        rpy="0 0 0" />
      <mass
        value="0.0083187" />
      <inertia
        ixx="3.4499E-06"
        ixy="-2.8195E-14"
        ixz="3.488E-13"
        iyy="1.5343E-06"
        iyz="-9.1438E-14"
        izz="2.8322E-06" />
    </inertial>
    <visual>
      <origin
        xyz="0 0 0"
        rpy="0 0 0" />
      <geometry>
        <mesh
          filename="package://handsfree_gazebo/meshes/servo_1_link.STL" />
      </geometry>
      <material
        name="">
        <color
          rgba="0.79608 0.82353 0.93725 1" />
      </material>
    </visual>
    <collision>
      <origin
        xyz="0 0 0"
        rpy="0 0 0" />
      <geometry>
        <mesh
          filename="package://handsfree_gazebo/meshes/servo_1_link.STL" />
      </geometry>
    </collision>
  </link>
  <joint
    name="servo_1"
    type="revolute">
    <origin
      xyz="0.15876 0 0.26675"
      rpy="0 -4.4188E-16 -4.9547E-15" />
    <parent
      link="base_link" />
    <child
      link="servo_1_link" />
    <axis
      xyz="0 0 -1" />
    <limit
      upper="1.5707"
      lower="-1.5707"
      effort="0.03"
      velocity="1" />
  </joint>
  <link
    name="servo_2_link">
    <inertial>
      <origin
        xyz="-0.00011403 -0.031349 0.00053785"
        rpy="0 0 0" />
      <mass
        value="0.072104" />
      <inertia
        ixx="6.2566E-05"
        ixy="2.927E-07"
        ixz="4.4175E-09"
        iyy="1.9721E-05"
        iyz="8.7621E-07"
        izz="5.2381E-05" />
    </inertial>
    <visual>
      <origin
        xyz="0 0 0"
        rpy="0 0 0" />
      <geometry>
        <mesh
          filename="package://handsfree_gazebo/meshes/servo_2_link.STL" />
      </geometry>
      <material
        name="">
        <color
          rgba="0.25098 0.25098 0.25098 1" />
      </material>
    </visual>
    <collision>
      <origin
        xyz="0 0 0"
        rpy="0 0 0" />
      <geometry>
        <mesh
          filename="package://handsfree_gazebo/meshes/servo_2_link.STL" />
      </geometry>
    </collision>
  </link>
  <joint
    name="servo_2"
    type="revolute">
    <origin
      xyz="0 0 0.04675"
      rpy="-1.5708 -1.3012E-14 -5.8344E-11" />
    <parent
      link="servo_1_link" />
    <child
      link="servo_2_link" />
    <axis
      xyz="0 0 -1" />
    <limit
      upper="1.5707"
      lower="-1.5707"
      effort="0.03"
      velocity="1" />
  </joint>
  <link
    name="xtion_link">
    <inertial>
      <origin
        xyz="5.5511E-17 -1.8209E-17 -5.5511E-17"
        rpy="0 0 0" />
      <mass
        value="0.30186" />
      <inertia
        ixx="0.00081582"
        ixy="-2.8823E-22"
        ixz="1.9523E-21"
        iyy="9.2473E-05"
        iyz="-4.029E-14"
        izz="0.00078252" />
    </inertial>
    <visual>
      <origin
        xyz="0 0 0"
        rpy="0 0 0" />
      <geometry>
        <mesh
          filename="package://handsfree_gazebo/meshes/xtion_link.STL" />
      </geometry>
      <material
        name="">
        <color
          rgba="0.75294 0.75294 0.75294 1" />
      </material>
    </visual>
    <collision>
      <origin
        xyz="0 0 0"
        rpy="0 0 0" />
      <geometry>
        <mesh
          filename="package://handsfree_gazebo/meshes/xtion_link.STL" />
      </geometry>
    </collision>
  </link>
  <joint
    name="xtion"
    type="fixed">
    <origin
      xyz="0 -0.09275 0"
      rpy="-1.5708 -1.7792E-16 -1.5708" />
    <parent
      link="servo_2_link" />
    <child
      link="xtion_link" />
    <axis
      xyz="0 0 0" />
  </joint>

<!--for xtion sensor model -->
      <joint name="xtion_depth_joint" type="fixed">
        <origin xyz="0.0 0.049 0.0" rpy="${M_PI} -${M_PI/2} 0" />
        <parent link="xtion_link" />
        <child link="xtion_depth_frame"/>
      </joint>

      <link name="xtion_depth_frame"/>

      <joint name="xtion_depth_optical_joint" type="fixed">
        <origin xyz="0 0 0" rpy="${-M_PI/2} 0.0 ${-M_PI/2}" />
        <parent link="xtion_depth_frame" />
        <child link="xtion_depth_optical_frame"/>
      </joint>

      <link name="xtion_depth_optical_frame"/>

      <joint name="xtion_rgb_joint" type="fixed">
        <origin xyz="0.0 0.022 0.0" rpy="0 0 0" />
        <parent link="xtion_link" />
        <child link="xtion_rgb_frame"/>
      </joint>

      <link name="xtion_rgb_frame"/>

      <joint name="xtion_rgb_optical_joint" type="fixed">
        <origin xyz="0 0 0" rpy="${-M_PI/2} 0.0 ${-M_PI/2}" />
        <parent link="xtion_rgb_frame" />
        <child link="xtion_rgb_optical_frame"/>
      </joint>

      <link name="xtion_rgb_optical_frame"/>

  </xacro:macro>
</robot>
