<robot
  name="stone_v3_base">
  <link
    name="base_link">
    <inertial>
      <origin
        xyz="-0.0011186 -4.317E-05 0.26842"
        rpy="0 0 0" />
      <mass
        value="9.7333" />
      <inertia
        ixx="0.86739"
        ixy="0"
        ixz="0"
        iyy="0.8309"
        iyz="0"
        izz="0.1541" />
    </inertial>
    <visual>
      <origin
        xyz="0 0 0"
        rpy="0 0 0" />
      <geometry>
        <mesh
          filename="package://handsfree_gazebo/urdf_stone_v3/meshes/base_link.STL" />
      </geometry>
      <material
        name="">
        <color
          rgba="0.33333 0.33333 0.33333 1" />
      </material>
    </visual>
    <collision>
      <origin
        xyz="0 0 0"
        rpy="0 0 0" />
      <geometry>
        <mesh
          filename="package://handsfree_gazebo/urdf_stone_v3/meshes/base_link.STL" />
      </geometry>
    </collision>
  </link>
  <link
    name="wheel_left_link">
    <inertial>
      <origin
        xyz="3.1631E-06 -7.2374E-08 -0.00032962"
        rpy="0 0 0" />
      <mass
        value="0.15338" />
      <inertia
        ixx="4.7342E-05"
        ixy="0"
        ixz="0"
        iyy="4.734E-05"
        iyz="0"
        izz="8.8619E-05" />
    </inertial>
    <visual>
      <origin
        xyz="0 0 0"
        rpy="0 0 0" />
      <geometry>
        <mesh
          filename="package://handsfree_gazebo/urdf_stone_v3/meshes/wheel_left_link.STL" />
      </geometry>
      <material
        name="">
        <color
          rgba="1 0.94902 0.89804 1" />
      </material>
    </visual>
    <collision>
      <origin
        xyz="0 0 0"
        rpy="0 0 0" />
      <geometry>
        <mesh
          filename="package://handsfree_gazebo/urdf_stone_v3/meshes/wheel_left_link.STL" />
      </geometry>
    </collision>
  </link>
  <joint
    name="wheel_left_joint"
    type="continuous">
    <origin
      xyz="0 0.1557 0.0124"
      rpy="-1.5708 0 0" />
    <parent
      link="base_link" />
    <child
      link="wheel_left_link" />
    <axis
      xyz="0 0 1" />
  </joint>
  <link
    name="wheel_right_link">
    <inertial>
      <origin
        xyz="-3.1631E-06 -7.2862E-08 -0.00032962"
        rpy="0 0 0" />
      <mass
        value="0.15338" />
      <inertia
        ixx="4.7342E-05"
        ixy="0"
        ixz="0"
        iyy="4.734E-05"
        iyz="0"
        izz="8.8619E-05" />
    </inertial>
    <visual>
      <origin
        xyz="0 0 0"
        rpy="0 0 0" />
      <geometry>
        <mesh
          filename="package://handsfree_gazebo/urdf_stone_v3/meshes/wheel_right_link.STL" />
      </geometry>
      <material
        name="">
        <color
          rgba="1 0.94902 0.89804 1" />
      </material>
    </visual>
    <collision>
      <origin
        xyz="0 0 0"
        rpy="0 0 0" />
      <geometry>
        <mesh
          filename="package://handsfree_gazebo/urdf_stone_v3/meshes/wheel_right_link.STL" />
      </geometry>
    </collision>
  </link>
  <joint
    name="wheel_right_joint"
    type="continuous">
    <origin
      xyz="0 -0.1557 0.0124"
      rpy="1.5708 0 0" />
    <parent
      link="base_link" />
    <child
      link="wheel_right_link" />
    <axis
      xyz="0 0 -1" />
  </joint>
  <link
    name="caster_front_link">
    <inertial>
      <origin
        xyz="0.0048088 0.0096311 8.3348E-16"
        rpy="0 0 0" />
      <mass
        value="0.29097" />
      <inertia
        ixx="0.00010851"
        ixy="0"
        ixz="0"
        iyy="7.011E-05"
        iyz="0"
        izz="0.00013847" />
    </inertial>
    <visual>
      <origin
        xyz="0 0 0"
        rpy="0 0 0" />
      <geometry>
        <mesh
          filename="package://handsfree_gazebo/urdf_stone_v3/meshes/caster_front_link.STL" />
      </geometry>
      <material
        name="">
        <color
          rgba="0.77647 0.75686 0.73725 1" />
      </material>
    </visual>
    <collision>
      <origin
        xyz="0 0 0"
        rpy="0 0 0" />
      <geometry>
        <mesh
          filename="package://handsfree_gazebo/urdf_stone_v3/meshes/caster_front_link.STL" />
      </geometry>
    </collision>
  </link>
  <joint
    name="caster_front_joint"
    type="floating">
    <origin
      xyz="0.126 0 -0.0006"
      rpy="1.5708 0 0" />
    <parent
      link="base_link" />
    <child
      link="caster_front_link" />
    <axis
      xyz="0 0 0" />
  </joint>
  <link
    name="caster_back_link">
    <inertial>
      <origin
        xyz="-0.0048088 0.0096311 8.3433E-16"
        rpy="0 0 0" />
      <mass
        value="0.29097" />
      <inertia
        ixx="0.00010851"
        ixy="0"
        ixz="0"
        iyy="7.011E-05"
        iyz="0"
        izz="0.00013847" />
    </inertial>
    <visual>
      <origin
        xyz="0 0 0"
        rpy="0 0 0" />
      <geometry>
        <mesh
          filename="package://handsfree_gazebo/urdf_stone_v3/meshes/caster_back_link.STL" />
      </geometry>
      <material
        name="">
        <color
          rgba="0.77647 0.75686 0.73725 1" />
      </material>
    </visual>
    <collision>
      <origin
        xyz="0 0 0"
        rpy="0 0 0" />
      <geometry>
        <mesh
          filename="package://handsfree_gazebo/urdf_stone_v3/meshes/caster_back_link.STL" />
      </geometry>
    </collision>
  </link>
  <joint
    name="caster_back_joint"
    type="floating">
    <origin
      xyz="-0.126 0 -0.0006"
      rpy="1.5708 0 0" />
    <parent
      link="base_link" />
    <child
      link="caster_back_link" />
    <axis
      xyz="0 0 0" />
  </joint>
  <link
    name="laser_link">
    <inertial>
      <origin
        xyz="-0.00012709 4.6538E-05 -0.011453"
        rpy="0 0 0" />
      <mass
        value="0.13632" />
      <inertia
        ixx="7.1499E-05"
        ixy="0"
        ixz="0"
        iyy="7.1883E-05"
        iyz="0"
        izz="4.6678E-05" />
    </inertial>
    <visual>
      <origin
        xyz="0 0 0"
        rpy="0 0 0" />
      <geometry>
        <mesh
          filename="package://handsfree_gazebo/urdf_stone_v3/meshes/laser_link.STL" />
      </geometry>
      <material
        name="">
        <color
          rgba="1 1 1 1" />
      </material>
    </visual>
    <collision>
      <origin
        xyz="0 0 0"
        rpy="0 0 0" />
      <geometry>
        <mesh
          filename="package://handsfree_gazebo/urdf_stone_v3/meshes/laser_link.STL" />
      </geometry>
    </collision>
  </link>
  <joint
    name="laser_joint"
    type="fixed">
    <origin
      xyz="0.145 0 0.14203"
      rpy="0 0 0" />
    <parent
      link="base_link" />
    <child
      link="laser_link" />
    <axis
      xyz="0 0 0" />
  </joint>
  <link
    name="yaw_link">
    <inertial>
      <origin
        xyz="8.5422E-05 0.0001613 0.0023545"
        rpy="0 0 0" />
      <mass
        value="0.15082" />
      <inertia
        ixx="0.00012558"
        ixy="0"
        ixz="0"
        iyy="0.00012402"
        iyz="0"
        izz="0.00023372" />
    </inertial>
    <visual>
      <origin
        xyz="0 0 0"
        rpy="0 0 0" />
      <geometry>
        <mesh
          filename="package://handsfree_gazebo/urdf_stone_v3/meshes/yaw_link.STL" />
      </geometry>
      <material
        name="">
        <color
          rgba="0.89804 0.91765 0.92941 1" />
      </material>
    </visual>
    <collision>
      <origin
        xyz="0 0 0"
        rpy="0 0 0" />
      <geometry>
        <mesh
          filename="package://handsfree_gazebo/urdf_stone_v3/meshes/yaw_link.STL" />
      </geometry>
    </collision>
  </link>
  <joint
    name="yaw_joint"
    type="revolute">
    <origin
      xyz="0 0 0.894"
      rpy="0 0 0" />
    <parent
      link="base_link" />
    <child
      link="yaw_link" />
    <axis
      xyz="0 0 1" />
    <limit
      effort="0"
      velocity="0" />
  </joint>
  <link
    name="pitch_link">
    <inertial>
      <origin
        xyz="-0.00024079 -0.041896 -9.1768E-05"
        rpy="0 0 0" />
      <mass
        value="0.06208" />
      <inertia
        ixx="4.7571E-05"
        ixy="0"
        ixz="0"
        iyy="2.3344E-05"
        iyz="0"
        izz="3.516E-05" />
    </inertial>
    <visual>
      <origin
        xyz="0 0 0"
        rpy="0 0 0" />
      <geometry>
        <mesh
          filename="package://handsfree_gazebo/urdf_stone_v3/meshes/pitch_link.STL" />
      </geometry>
      <material
        name="">
        <color
          rgba="0.89804 0.91765 0.92941 1" />
      </material>
    </visual>
    <collision>
      <origin
        xyz="0 0 0"
        rpy="0 0 0" />
      <geometry>
        <mesh
          filename="package://handsfree_gazebo/urdf_stone_v3/meshes/pitch_link.STL" />
      </geometry>
    </collision>
  </link>
  <joint
    name="pitch_joint"
    type="revolute">
    <origin
      xyz="0.01 5E-05 0.01475"
      rpy="-1.5708 0 0" />
    <parent
      link="yaw_link" />
    <child
      link="pitch_link" />
    <axis
      xyz="0 0 1" />
    <limit
      effort="0"
      velocity="0" />
  </joint>
  <link
    name="xtion_link">
    <inertial>
      <origin
        xyz="-0.017766 1.5798E-06 -0.00017508"
        rpy="0 0 0" />
      <mass
        value="0.15757" />
      <inertia
        ixx="0.00039792"
        ixy="0"
        ixz="0"
        iyy="2.4687E-05"
        iyz="0"
        izz="0.00040604" />
    </inertial>
    <visual>
      <origin
        xyz="0 0 0"
        rpy="0 0 0" />
      <geometry>
        <mesh
          filename="package://handsfree_gazebo/urdf_stone_v3/meshes/xtion_link.STL" />
      </geometry>
      <material
        name="">
        <color
          rgba="0.33333 0.33333 0.33333 1" />
      </material>
    </visual>
    <collision>
      <origin
        xyz="0 0 0"
        rpy="0 0 0" />
      <geometry>
        <mesh
          filename="package://handsfree_gazebo/urdf_stone_v3/meshes/xtion_link.STL" />
      </geometry>
    </collision>
  </link>
  <joint
    name="xtion_joint"
    type="fixed">
    <origin
      xyz="0.0181 -0.08706 0.00011573"
      rpy="1.5708 0 0" />
    <parent
      link="pitch_link" />
    <child
      link="xtion_link" />
    <axis
      xyz="0 0 0" />
  </joint>
</robot>
